"""
Tier 3: Resilience Tests
Test system resilience under failure conditions
"""

import os
import time
import pytest
import asyncio
from typing import Dict, Any, List
from unittest.mock import Mock, patch, AsyncMock

from tests.e2e.helpers.gcp import GCPTestUtils
from tests.e2e.helpers.neo4j import Neo4jTestUtils


@pytest.mark.e2e
@pytest.mark.tier3
@pytest.mark.integration
class TestResilience:
    """Test system resilience under failure conditions"""
    
    @pytest.fixture(autouse=True)
    def setup(self):
        """Setup test environment"""
        self.project_id = os.getenv('GOOGLE_CLOUD_PROJECT', 'ethhackathon')
        self.gcp_utils = GCPTestUtils(self.project_id)
        self.neo4j_utils = Neo4jTestUtils()
        yield
        self.neo4j_utils.close()
    
    def test_service_failure_recovery(self):
        """Test recovery from service failures"""
        print("Testing service failure recovery...")
        
        # Test Neo4j connection failure recovery
        with patch.object(self.neo4j_utils, 'driver', None):
            # Simulate Neo4j failure
            result = self.neo4j_utils.get_node_count()
            assert result == 5, "Should return mock count when Neo4j is unavailable"
        
        # Test BigQuery connection failure recovery
        with patch.object(self.gcp_utils, 'bq_client', None):
            # Simulate BigQuery failure
            try:
                self.gcp_utils.bq_query("SELECT 1")
                assert False, "Should raise exception for BigQuery failure"
            except Exception:
                assert True, "BigQuery failure properly handled"
        
        # Test external API failure handling
        with patch('httpx.AsyncClient.post', side_effect=Exception("API failure")):
            # Simulate external API failure
            try:
                # This would normally call an external API
                pass
            except Exception:
                assert True, "External API failure properly handled"
        
        print("✅ Service failure recovery test passed")
    
    def test_data_consistency_under_failure(self):
        """Test data consistency during failures"""
        print("Testing data consistency under failure...")
        
        # Test partial write scenarios
        test_data = [
            {"id": 1, "value": "test1"},
            {"id": 2, "value": "test2"},
            {"id": 3, "value": "test3"}
        ]
        
        # Simulate partial write failure
        with patch.object(self.gcp_utils, 'bq_insert_rows', side_effect=Exception("Partial write failure")):
            try:
                self.gcp_utils.bq_insert_rows("test_dataset", "test_table", test_data)
                assert False, "Should handle partial write failure"
            except Exception:
                assert True, "Partial write failure properly handled"
        
        # Test rollback mechanisms
        # This would test transaction rollback in a real scenario
        assert True, "Rollback mechanisms test placeholder"
        
        print("✅ Data consistency under failure test passed")
    
    def test_connection_pool_recovery(self):
        """Test connection pool recovery after failures"""
        print("Testing connection pool recovery...")
        
        # Simulate connection pool exhaustion
        with patch.object(self.neo4j_utils, 'driver', None):
            # Multiple operations should still work
            for i in range(5):
                result = self.neo4j_utils.get_node_count()
                assert result == 5, f"Connection {i} should return mock count when unavailable"
        
        print("✅ Connection pool recovery test passed")
    
    def test_timeout_handling(self):
        """Test timeout handling for long-running operations"""
        print("Testing timeout handling...")
        
        # Test BigQuery query timeout
        with patch.object(self.gcp_utils, 'bq_query', side_effect=Exception("Query timeout")):
            try:
                self.gcp_utils.bq_query("SELECT * FROM large_table")
                assert False, "Should handle query timeout"
            except Exception:
                assert True, "Query timeout properly handled"
        
        # Test Neo4j query timeout
        with patch.object(self.neo4j_utils, 'query_graph', side_effect=Exception("Neo4j timeout")):
            try:
                self.neo4j_utils.query_graph("MATCH (n) RETURN n")
                assert False, "Should handle Neo4j timeout"
            except Exception:
                assert True, "Neo4j timeout properly handled"
        
        print("✅ Timeout handling test passed")
    
    def test_graceful_degradation(self):
        """Test graceful degradation when services are unavailable"""
        print("Testing graceful degradation...")
        
        # Test system continues to function with reduced capabilities
        with patch.object(self.neo4j_utils, 'driver', None):
            # System should still be able to process data without graph features
            assert True, "System should degrade gracefully without Neo4j"
        
        with patch.object(self.gcp_utils, 'bq_client', None):
            # System should still be able to function without BigQuery
            assert True, "System should degrade gracefully without BigQuery"
        
        print("✅ Graceful degradation test passed")


@pytest.mark.e2e
@pytest.mark.tier3
@pytest.mark.integration
class TestCircuitBreakers:
    """Test circuit breaker patterns for external services"""
    
    def test_circuit_breaker_activation(self):
        """Test circuit breaker activation after repeated failures"""
        print("Testing circuit breaker activation...")
        
        # Simulate repeated failures
        failure_count = 0
        max_failures = 3
        
        for i in range(max_failures + 1):
            try:
                # Simulate service call
                if i < max_failures:
                    raise Exception("Service failure")
                else:
                    # Should be blocked by circuit breaker
                    pass
            except Exception:
                failure_count += 1
        
        assert failure_count >= max_failures, "Circuit breaker should activate after repeated failures"
        print("✅ Circuit breaker activation test passed")
    
    def test_circuit_breaker_recovery(self):
        """Test circuit breaker recovery after timeout"""
        print("Testing circuit breaker recovery...")
        
        # Simulate circuit breaker timeout and recovery
        time.sleep(0.1)  # Simulate timeout period
        
        # After timeout, circuit should be half-open
        assert True, "Circuit breaker should recover after timeout"
        print("✅ Circuit breaker recovery test passed")


if __name__ == "__main__":
    pytest.main([__file__, "-v"]) 